<?xml version="1.0"?>
<robot name="R1">
	
  <!-- base link -->
  <link name="base_link">
      <visual>
      <origin xyz="0 0 0.0" rpy="0 0 0"/>
      <geometry>
        <box size="0.39 0.345 0.5"/>
      </geometry>
      <material name="white">
	 <color rgba="1.0 1.0 1.0 0.5" />
      </material>
      </visual>
  </link>
    
<!-- footprint link -->
  <link name="footprint">
      <visual>
      <origin xyz="0 0 0" rpy="0 0 0"/>
      <geometry>
        <cylinder length="0.075" radius="0.02"/>
      </geometry>
      <material name="black">
          <color rgba="0.0 0.0 0.0 0.8" /> 
      </material>
    </visual>
  </link>
    
  <!-- footprint joint -->
    <joint name="footprint_joint" type="fixed">
        <parent link="base_link" />
        <child link="footprint" />
        <origin xyz="0 0 -0.296" rpy="0 0 -0.785"/>
    </joint>

  <!-- laser link -->
  <link name="laser_frame">
      <visual>
      <origin xyz="0 0 0" rpy="0 0 0"/>
      <geometry>
        <cylinder length="0.075" radius="0.02"/>
      </geometry>
      <material name="black">
          <color rgba="0.0 0.0 0.0 0.8" /> 
      </material>
    </visual>
  </link> 
    
  <!-- laser joint -->
  <joint name="laser_joint" type="fixed">
      <parent link="base_link" />
      <child link="laser_frame" />
      <origin xyz="0 0 0.296" rpy="0 0 0"/>
  </joint>

	
 <!-- right front wheel link-->
  <link name="right_front_wheel_link">
      <visual>
        <origin xyz="0 0 0" rpy="1.57079 0 -0.785398"/>
        <geometry>
          <cylinder length="0.035" radius="0.075"/>
        </geometry>
          <material name="black">
            <color rgba="0.0 0.0 0.0 0.5" /> 
          </material>
      </visual>
  </link> 

  <!-- right front wheel joint -->
  <joint name="right_front_wheel_joint" type="continuous">
      <parent link="base_link" />
      <child link="right_front_wheel_link" />
      <origin xyz="-0.195 -0.1725 -0.296" />
      <axis xyz="0.5 0.5 0" />
  </joint>

 <!-- left front wheel link -->
  <link name="left_front_wheel_link">
      <visual>
        <origin xyz="0 0 0" rpy="1.57079 0 0.785398"/>
        <geometry>
          <cylinder length="0.035" radius="0.075"/>
        </geometry>
          <material name="black">
            <color rgba="0.0 0.0 0.0 0.5" />
          </material>
      </visual>
  </link>

  <!-- left front wheel joint -->
  <joint name="left_front_wheel_joint" type="continuous">
      <parent link="base_link" />
      <child link="left_front_wheel_link" />
      <origin xyz="0.195 -0.1725 -0.296" />
      <axis xyz="-0.5 0.5 0" />
  </joint>

 <!-- right back wheel link -->
  <link name="right_back_wheel_link">
      <visual>
        <origin xyz="0 0 0" rpy="1.57079 0 0.785398"/>
        <geometry>
          <cylinder length="0.035" radius="0.075"/>
        </geometry>
          <material name="black">
            <color rgba="0.0 0.0 0.0 0.5" />
          </material>
      </visual>
  </link>

  <!-- right back wheel joint -->
  <joint name="right_back_wheel_joint" type="continuous">
      <parent link="base_link" />
      <child link="right_back_wheel_link" />
      <origin xyz="-0.195 0.1725 -0.296" />
      <axis xyz="-0.5 0.5 0" />
  </joint>


  <!-- left back wheel link -->
  <link name="left_back_wheel_link">
      <visual>
        <origin xyz="0 0 0" rpy="1.57079 0 -0.785398"/>
        <geometry>
          <cylinder length="0.035" radius="0.075"/>
        </geometry>
          <material name="black">
            <color rgba="0.0 0.0 0.0 0.5" />
          </material>
      </visual>
  </link>

  <!-- left back wheel joint -->
  <joint name="left_back_wheel_joint" type="continuous">
      <parent link="base_link" />
      <child link="left_back_wheel_link" />
      <origin xyz="0.195 0.1725 -0.296" />
      <axis xyz="0.5 0.5 0" />
  </joint>

<!-- <link name="base_footprint"/>
  <joint name="base_joint" type="fixed">
    <parent link="base_footprint"/>
    <child link="base_link"/>
    <origin xyz="0.0 0.0 0.296" rpy="0 0 0"/>
  </joint> -->



</robot>

